Workbook
Name Student_code: Database_Unique_Code!$B$4
Name student_name: Database_Unique_Code!$C$4

Sheet Database_Unique_Code
P1: Attendance Data
J3: Students Assessment Marks | P3: =AVERAGEIF(P5:P999,">0") -> 0.78571429 | Q3: =AVERAGEIF(Q5:Q999,">0") -> 0.79397436 | R3: =AVERAGEIF(R5:R999,">0") -> 0.78362573 | S3: =AVERAGEIF(S5:S999,">0") -> 0.78956229 | T3: =AVERAGEIF(T5:T999,">0") -> 0.77692308 | U3: =AVERAGEIF(U5:U999,">0") -> 0.76148148 | V3: =AVERAGEIF(V5:V999,">0") -> 0.78746914 | W3: =AVERAGEIF(W5:W999,">0") -> 0.80148148 | ... Z3: =AVERAGEIF(Z5:Z999,">0") -> 0.72
A4: Sr. no | B4: Unique Code | C4: Name of student | D4: Std | E4: Gender | F4: Contact Number | G4: Favourite Hobby | H4: Year of Joining in Abhyasika | I4: Status | J4: July | K4: Aug | L4: sep | M4: Dec | N4: Jan | O4: Feb | P4: =Attendance_data!B4 -> 45809 | Q4: =Attendance_data!B34 -> 45839 | R4: =Attendance_data!B65 -> 45870 | S4: =Attendance_data!B96 -> 45901 | T4: =Attendance_data!B126 -> 45931 | U4: =Attendance_data!B157 -> 45962 | V4: =Attendance_data!B187 -> 45992 | W4: =Attendance_data!B240 -> 46023 | X4: =Attendance_data!B250 -> 46054 | Y4: =Attendance_data!B292 -> 46082 | Z4: =Attendance_data!B324 -> 46113 | AB4: Overall attendance
A5: =ROW()-4 -> 1 | B5: NMUD01 | C5: Tanishka chandrakant bordekar | D5: 7th | E5: Girl | F5: 8108416756 | G5: Singing | H5: 2018 | I5: Active | J5: 25 | K5: 23 | L5: 25 | M5: 26 | N5: 30 | O5: 24 | P5: {=IFERROR( COUNTIFS(Attendance_data!$B$4:$B$1000,P$4, INDIRECT("Attendance_data!" & ADDRESS(4, MATCH($B5, Attendance_data!$E$3:$BI$3, 0) + 4) & ":" & ADDRESS(1000, MATCH($B5, Attendance_data!$E$3:$BI$3, 0) + 4)), "P" ) / ( COUNTIFS( Attendance_data!$B$4:$B$1000,P$4, INDIRECT("Attendance_data!" & ADDRESS(4, MATCH($B5, Attendance_data!$E$3:$BI$3, 0) + 4) & ":" & ADDRESS(1000, MATCH($B5, Attendance_data!$E$3:$BI$3, 0) + 4)), "P" ) + COUNTIFS( Attendance_data!$B$4:$B$1000,P$4, INDIRECT("Attendance_data!" & ADDRESS(4, MATCH($B5, Attendance_data!$E$3:$BI$3, 0) + 4) & ":" & ADDRESS(1000, MATCH($B5, Attendance_data!$E$3:$BI$3, 0) + 4)), "A" ) ),"")} -> 0.095238095 | Q5: {=IFERROR( COUNTIFS(Attendance_data!$B$4:$B$1000,Q$4, INDIRECT("Attendance_data!" & ADDRESS(4, MATCH($B5, Attendance_data!$E$3:$BI$3, 0) + 4) & ":" & ADDRESS(1000, MATCH($B5, Attendance_data!$E$3:$BI$3, 0) + 4)), "P" ) / ( COUNTIFS( Attendance_data!$B$4:$B$1000,Q$4, INDIRECT("Attendance_data!" & ADDRESS(4, MATCH($B5, Attendance_data!$E$3:$BI$3, 0) + 4) & ":" & ADDRESS(1000, MATCH($B5, Attendance_data!$E$3:$BI$3, 0) + 4)), "P" ) + COUNTIFS( Attendance_data!$B$4:$B$1000,Q$4, INDIRECT("Attendance_data!" & ADDRESS(4, MATCH($B5, Attendance_data!$E$3:$BI$3, 0) + 4) & ":" & ADDRESS(1000, MATCH($B5, Attendance_data!$E$3:$BI$3, 0) + 4)), "A" ) ),"")} -> 0.23076923 | R5: {=IFERROR( COUNTIFS(Attendance_data!$B$4:$B$1000,R$4, INDIRECT("Attendance_data!" & ADDRESS(4, MATCH($B5, Attendance_data!$E$3:$BI$3, 0) + 4) & ":" & ADDRESS(1000, MATCH($B5, Attendance_data!$E$3:$BI$3, 0) + 4)), "P" ) / ( COUNTIFS( Attendance_data!$B$4:$B$1000,R$4, INDIRECT("Attendance_data!" & ADDRESS(4, MATCH($B5, Attendance_data!$E$3:$BI$3, 0) + 4) & ":" & ADDRESS(1000, MATCH($B5, Attendance_data!$E$3:$BI$3, 0) + 4)), "P" ) + COUNTIFS( Attendance_data!$B$4:$B$1000,R$4, INDIRECT("Attendance_data!" & ADDRESS(4, MATCH($B5, Attendance_data!$E$3:$BI$3, 0) + 4) & ":" & ADDRESS(1000, MATCH($B5, Attendance_data!$E$3:$BI$3, 0) + 4)), "A" ) ),"")} -> 0.26315789 | S5: {=IFERROR( COUNTIFS(Attendance_data!$B$4:$B$1000,S$4, INDIRECT("Attendance_data!" & ADDRESS(4, MATCH($B5, Attendance_data!$E$3:$BI$3, 0) + 4) & ":" & ADDRESS(1000, MATCH($B5, Attendance_data!$E$3:$BI$3, 0) + 4)), "P" ) / ( COUNTIFS( Attendance_data!$B$4:$B$1000,S$4, INDIRECT("Attendance_data!" & ADDRESS(4, MATCH($B5, Attendance_data!$E$3:$BI$3, 0) + 4) & ":" & ADDRESS(1000, MATCH($B5, Attendance_data!$E$3:$BI$3, 0) + 4)), "P" ) + COUNTIFS( Attendance_data!$B$4:$B$1000,S$4, INDIRECT("Attendance_data!" & ADDRESS(4, MATCH($B5, Attendance_data!$E$3:$BI$3, 0) + 4) & ":" & ADDRESS(1000, MATCH($B5, Attendance_data!$E$3:$BI$3, 0) + 4)), "A" ) ),"")} -> 0.045454545 | T5: {=IFERROR( COUNTIFS(Attendance_data!$B$4:$B$1000,T$4, INDIRECT("Attendance_data!" & ADDRESS(4, MATCH($B5, Attendance_data!$E$3:$BI$3, 0) + 4) & ":" & ADDRESS(1000, MATCH($B5, Attendance_data!$E$3:$BI$3, 0) + 4)), "P" ) / ( COUNTIFS( Attendance_data!$B$4:$B$1000,T$4, INDIRECT("Attendance_data!" & ADDRESS(4, MATCH($B5, Attendance_data!$E$3:$BI$3, 0) + 4) & ":" & ADDRESS(1000, MATCH($B5, Attendance_data!$E$3:$BI$3, 0) + 4)), "P" ) + COUNTIFS( Attendance_data!$B$4:$B$1000,T$4, INDIRECT("Attendance_data!" & ADDRESS(4, MATCH($B5, Attendance_data!$E$3:$BI$3, 0) + 4) & ":" & ADDRESS(1000, MATCH($B5, Attendance_data!$E$3:$BI$3, 0) + 4)), "A" ) ),"")} -> 0.1 | U5: {=IFERROR( COUNTIFS(Attendance_data!$B$4:$B$1000,U$4, INDIRECT("Attendance_data!" & ADDRESS(4, MATCH($B5, Attendance_data!$E$3:$BI$3, 0) + 4) & ":" & ADDRESS(1000, MATCH($B5, Attendance_data!$E$3:$BI$3, 0) + 4)), "P" ) / ( COUNTIFS( Attendance_data!$B$4:$B$1000,U$4, INDIRECT("Attendance_data!" & ADDRESS(4, MATCH($B5, Attendance_data!$E$3:$BI$3, 0) + 4) & ":" & ADDRESS(1000, MATCH($B5, Attendance_data!$E$3:$BI$3, 0) + 4)), "P" ) + COUNTIFS( Attendance_data!$B$4:$B$1000,U$4, INDIRECT("Attendance_data!" & ADDRESS(4, MATCH($B5, Attendance_data!$E$3:$BI$3, 0) + 4) & ":" & ADDRESS(1000, MATCH($B5, Attendance_data!$E$3:$BI$3, 0) + 4)), "A" ) ),"")} -> 0.2 | V5: {=IFERROR( COUNTIFS(Attendance_data!$B$4:$B$1000,V$4, INDIRECT("Attendance_data!" & ADDRESS(4, MATCH($B5, Attendance_data!$E$3:$BI$3, 0) + 4) & ":" & ADDRESS(1000, MATCH($B5, Attendance_data!$E$3:$BI$3, 0) + 4)), "P" ) / ( COUNTIFS( Attendance_data!$B$4:$B$1000,V$4, INDIRECT("Attendance_data!" & ADDRESS(4, MATCH($B5, Attendance_data!$E$3:$BI$3, 0) + 4) & ":" & ADDRESS(1000, MATCH($B5, Attendance_data!$E$3:$BI$3, 0) + 4)), "P" ) + COUNTIFS( Attendance_data!$B$4:$B$1000,V$4, INDIRECT("Attendance_data!" & ADDRESS(4, MATCH($B5, Attendance_data!$E$3:$BI$3, 0) + 4) & ":" & ADDRESS(1000, MATCH($B5, Attendance_data!$E$3:$BI$3, 0) + 4)), "A" ) ),"")} -> 0.4 | W5: {=IFERROR( COUNTIFS(Attendance_data!$B$4:$B$1000,W$4, INDIRECT("Attendance_data!" & ADDRESS(4, MATCH($B5, Attendance_data!$E$3:$BI$3, 0) + 4) & ":" & ADDRESS(1000, MATCH($B5, Attendance_data!$E$3:$BI$3, 0) + 4)), "P" ) / ( COUNTIFS( Attendance_data!$B$4:$B$1000,W$4, INDIRECT("Attendance_data!" & ADDRESS(4, MATCH($B5, Attendance_data!$E$3:$BI$3, 0) + 4) & ":" & ADDRESS(1000, MATCH($B5, Attendance_data!$E$3:$BI$3, 0) + 4)), "P" ) + COUNTIFS( Attendance_data!$B$4:$B$1000,W$4, INDIRECT("Attendance_data!" & ADDRESS(4, MATCH($B5, Attendance_data!$E$3:$BI$3, 0) + 4) & ":" & ADDRESS(1000, MATCH($B5, Attendance_data!$E$3:$BI$3, 0) + 4)), "A" ) ),"")} -> 0.56 | ... AA5: {=IFERROR( COUNTIFS(Attendance_data!$B$4:$B$1000,AA$4, INDIRECT("Attendance_data!" & ADDRESS(4, MATCH($B5, Attendance_data!$E$3:$BI$3, 0) + 4) & ":" & ADDRESS(1000, MATCH($B5, Attendance_data!$E$3:$BI$3, 0) + 4)), "P" ) / ( COUNTIFS( Attendance_data!$B$4:$B$1000,AA$4, INDIRECT("Attendance_data!" & ADDRESS(4, MATCH($B5, Attendance_data!$E$3:$BI$3, 0) + 4) & ":" & ADDRESS(1000, MATCH($B5, Attendance_data!$E$3:$BI$3, 0) + 4)), "P" ) + COUNTIFS( Attendance_data!$B$4:$B$1000,AA$4, INDIRECT("Attendance_data!" & ADDRESS(4, MATCH($B5, Attendance_data!$E$3:$BI$3, 0) + 4) & ":" & ADDRESS(1000, MATCH($B5, Attendance_data!$E$3:$BI$3, 0) + 4)), "A" ) ),"")} | AB5: =AVERAGEIF(P5:Z5,">0") -> 0.2846119
A6: =ROW()-4 -> 2 | B6: NMUD02 | C6: Rashi vitthal sakharkar | D6: 8th | E6: Girl | F6: 9653608041 | G6: Drawing | H6: 2019 | I6: Active | J6: 25 | K6: 21 | L6: 22 | M6: 25 | N6: 24 | O6: 18 | P6: {=IFERROR( COUNTIFS(Attendance_data!$B$4:$B$1000,P$4, INDIRECT("Attendance_data!" & ADDRESS(4, MATCH($B6, Attendance_data!$E$3:$BI$3, 0) + 4) & ":" & ADDRESS(1000, MATCH($B6, Attendance_data!$E$3:$BI$3, 0) + 4)), "P" ) / ( COUNTIFS( Attendance_data!$B$4:$B$1000,P$4, INDIRECT("Attendance_data!" & ADDRESS(4, MATCH($B6, Attendance_data!$E$3:$BI$3, 0) + 4) & ":" & ADDRESS(1000, MATCH($B6, Attendance_data!$E$3:$BI$3, 0) + 4)), "P" ) + COUNTIFS( Attendance_data!$B$4:$B$1000,P$4, INDIRECT("Attendance_data!" & ADDRESS(4, MATCH($B6, Attendance_data!$E$3:$BI$3, 0) + 4) & ":" & ADDRESS(1000, MATCH($B6, Attendance_data!$E$3:$BI$3, 0) + 4)), "A" ) ),"")} -> 0.76190476 | Q6: {=IFERROR( COUNTIFS(Attendance_data!$B$4:$B$1000,Q$4, INDIRECT("Attendance_data!" & ADDRESS(4, MATCH($B6, Attendance_data!$E$3:$BI$3, 0) + 4) & ":" & ADDRESS(1000, MATCH($B6, Attendance_data!$E$3:$BI$3, 0) + 4)), "P" ) / ( COUNTIFS( Attendance_data!$B$4:$B$1000,Q$4, INDIRECT("Attendance_data!" & ADDRESS(4, MATCH($B6, Attendance_data!$E$3:$BI$3, 0) + 4) & ":" & ADDRESS(1000, MATCH($B6, Attendance_data!$E$3:$BI$3, 0) + 4)), "P" ) + COUNTIFS( Attendance_data!$B$4:$B$1000,Q$4, INDIRECT("Attendance_data!" & ADDRESS(4, MATCH($B6, Attendance_data!$E$3:$BI$3, 0) + 4) & ":" & ADDRESS(1000, MATCH($B6, Attendance_data!$E$3:$BI$3, 0) + 4)), "A" ) ),"")} -> 0.84615385 | R6: {=IFERROR( COUNTIFS(Attendance_data!$B$4:$B$1000,R$4, INDIRECT("Attendance_data!" & ADDRESS(4, MATCH($B6, Attendance_data!$E$3:$BI$3, 0) + 4) & ":" & ADDRESS(1000, MATCH($B6, Attendance_data!$E$3:$BI$3, 0) + 4)), "P" ) / ( COUNTIFS( Attendance_data!$B$4:$B$1000,R$4, INDIRECT("Attendance_data!" & ADDRESS(4, MATCH($B6, Attendance_data!$E$3:$BI$3, 0) + 4) & ":" & ADDRESS(1000, MATCH($B6, Attendance_data!$E$3:$BI$3, 0) + 4)), "P" ) + COUNTIFS( Attendance_data!$B$4:$B$1000,R$4, INDIRECT("Attendance_data!" & ADDRESS(4, MATCH($B6, Attendance_data!$E$3:$BI$3, 0) + 4) & ":" & ADDRESS(1000, MATCH($B6, Attendance_data!$E$3:$BI$3, 0) + 4)), "A" ) ),"")} -> 0.94736842 | S6: {=IFERROR( COUNTIFS(Attendance_data!$B$4:$B$1000,S$4, INDIRECT("Attendance_data!" & ADDRESS(4, MATCH($B6, Attendance_data!$E$3:$BI$3, 0) + 4) & ":" & ADDRESS(1000, MATCH($B6, Attendance_data!$E$3:$BI$3, 0) + 4)), "P" ) / ( COUNTIFS( Attendance_data!$B$4:$B$1000,S$4, INDIRECT("Attendance_data!" & ADDRESS(4, MATCH($B6, Attendance_data!$E$3:$BI$3, 0) + 4) & ":" & ADDRESS(1000, MATCH($B6, Attendance_data!$E$3:$BI$3, 0) + 4)), "P" ) + COUNTIFS( Attendance_data!$B$4:$B$1000,S$4, INDIRECT("Attendance_data!" & ADDRESS(4, MATCH($B6, Attendance_data!$E$3:$BI$3, 0) + 4) & ":" & ADDRESS(1000, MATCH($B6, Attendance_data!$E$3:$BI$3, 0) + 4)), "A" ) ),"")} -> 0.95454545 | T6: {=IFERROR( COUNTIFS(Attendance_data!$B$4:$B$1000,T$4, INDIRECT("Attendance_data!" & ADDRESS(4, MATCH($B6, Attendance_data!$E$3:$BI$3, 0) + 4) & ":" & ADDRESS(1000, MATCH($B6, Attendance_data!$E$3:$BI$3, 0) + 4)), "P" ) / ( COUNTIFS( Attendance_data!$B$4:$B$1000,T$4, INDIRECT("Attendance_data!" & ADDRESS(4, MATCH($B6, Attendance_data!$E$3:$BI$3, 0) + 4) & ":" & ADDRESS(1000, MATCH($B6, Attendance_data!$E$3:$BI$3, 0) + 4)), "P" ) + COUNTIFS( Attendance_data!$B$4:$B$1000,T$4, INDIRECT("Attendance_data!" & ADDRESS(4, MATCH($B6, Attendance_data!$E$3:$BI$3, 0) + 4) & ":" & ADDRESS(1000, MATCH($B6, Attendance_data!$E$3:$BI$3, 0) + 4)), "A" ) ),"")} -> 0.7 | U6: {=IFERROR( COUNTIFS(Attendance_data!$B$4:$B$1000,U$4, INDIRECT("Attendance_data!" & ADDRESS(4, MATCH($B6, Attendance_data!$E$3:$BI$3, 0) + 4) & ":" & ADDRESS(1000, MATCH($B6, Attendance_data!$E$3:$BI$3, 0) + 4)), "P" ) / ( COUNTIFS( Attendance_data!$B$4:$B$1000,U$4, INDIRECT("Attendance_data!" & ADDRESS(4, MATCH($B6, Attendance_data!$E$3:$BI$3, 0) + 4) & ":" & ADDRESS(1000, MATCH($B6, Attendance_data!$E$3:$BI$3, 0) + 4)), "P" ) + COUNTIFS( Attendance_data!$B$4:$B$1000,U$4, INDIRECT("Attendance_data!" & ADDRESS(4, MATCH($B6, Attendance_data!$E$3:$BI$3, 0) + 4) & ":" & ADDRESS(1000, MATCH($B6, Attendance_data!$E$3:$BI$3, 0) + 4)), "A" ) ),"")} -> 0.84 | V6: {=IFERROR( COUNTIFS(Attendance_data!$B$4:$B$1000,V$4, INDIRECT("Attendance_data!" & ADDRESS(4, MATCH($B6, Attendance_data!$E$3:$BI$3, 0) + 4) & ":" & ADDRESS(1000, MATCH($B6, Attendance_data!$E$3:$BI$3, 0) + 4)), "P" ) / ( COUNTIFS( Attendance_data!$B$4:$B$1000,V$4, INDIRECT("Attendance_data!" & ADDRESS(4, MATCH($B6, Attendance_data!$E$3:$BI$3, 0) + 4) & ":" & ADDRESS(1000, MATCH($B6, Attendance_data!$E$3:$BI$3, 0) + 4)), "P" ) + COUNTIFS( Attendance_data!$B$4:$B$1000,V$4, INDIRECT("Attendance_data!" & ADDRESS(4, MATCH($B6, Attendance_data!$E$3:$BI$3, 0) + 4) & ":" & ADDRESS(1000, MATCH($B6, Attendance_data!$E$3:$BI$3, 0) + 4)), "A" ) ),"")} -> 0.92 | W6: {=IFERROR( COUNTIFS(Attendance_data!$B$4:$B$1000,W$4, INDIRECT("Attendance_data!" & ADDRESS(4, MATCH($B6, Attendance_data!$E$3:$BI$3, 0) + 4) & ":" & ADDRESS(1000, MATCH($B6, Attendance_data!$E$3:$BI$3, 0) + 4)), "P" ) / ( COUNTIFS( Attendance_data!$B$4:$B$1000,W$4, INDIRECT("Attendance_data!" & ADDRESS(4, MATCH($B6, Attendance_data!$E$3:$BI$3, 0) + 4) & ":" & ADDRESS(1000, MATCH($B6, Attendance_data!$E$3:$BI$3, 0) + 4)), "P" ) + COUNTIFS( Attendance_data!$B$4:$B$1000,W$4, INDIRECT("Attendance_data!" & ADDRESS(4, MATCH($B6, Attendance_data!$E$3:$BI$3, 0) + 4) & ":" & ADDRESS(1000, MATCH($B6, Attendance_data!$E$3:$BI$3, 0) + 4)), "A" ) ),"")} -> 0.96 | ... AA6: {=IFERROR( COUNTIFS(Attendance_data!$B$4:$B$1000,AA$4, INDIRECT("Attendance_data!" & ADDRESS(4, MATCH($B6, Attendance_data!$E$3:$BI$3, 0) + 4) & ":" & ADDRESS(1000, MATCH($B6, Attendance_data!$E$3:$BI$3, 0) + 4)), "P" ) / ( COUNTIFS( Attendance_data!$B$4:$B$1000,AA$4, INDIRECT("Attendance_data!" & ADDRESS(4, MATCH($B6, Attendance_data!$E$3:$BI$3, 0) + 4) & ":" & ADDRESS(1000, MATCH($B6, Attendance_data!$E$3:$BI$3, 0) + 4)), "P" ) + COUNTIFS( Attendance_data!$B$4:$B$1000,AA$4, INDIRECT("Attendance_data!" & ADDRESS(4, MATCH($B6, Attendance_data!$E$3:$BI$3, 0) + 4) & ":" & ADDRESS(1000, MATCH($B6, Attendance_data!$E$3:$BI$3, 0) + 4)), "A" ) ),"")} | AB6: =AVERAGEIF(P6:Z6,">0") -> 0.86484598
A7: =ROW()-4 -> 3 | B7: NMUD05 | C7: Rakhi vitthal sakharkar | D7: 10th | E7: Girl | F7: 9324299943 | G7: Dance | H7: 2018 | I7: Active | J7: 24 | K7: 19 | L7: 28 | M7: 17 | N7: 26 | O7: NA | P7: {=IFERROR( COUNTIFS(Attendance_data!$B$4:$B$1000,P$4, INDIRECT("Attendance_data!" & ADDRESS(4, MATCH($B7, Attendance_data!$E$3:$BI$3, 0) + 4) & ":" & ADDRESS(1000, MATCH($B7, Attendance_data!$E$3:$BI$3, 0) + 4)), "P" ) / ( COUNTIFS( Attendance_data!$B$4:$B$1000,P$4, INDIRECT("Attendance_data!" & ADDRESS(4, MATCH($B7, Attendance_data!$E$3:$BI$3, 0) + 4) & ":" & ADDRESS(1000, MATCH($B7, Attendance_data!$E$3:$BI$3, 0) + 4)), "P" ) + COUNTIFS( Attendance_data!$B$4:$B$1000,P$4, INDIRECT("Attendance_data!" & ADDRESS(4, MATCH($B7, Attendance_data!$E$3:$BI$3, 0) + 4) & ":" & ADDRESS(1000, MATCH($B7, Attendance_data!$E$3:$BI$3, 0) + 4)), "A" ) ),"")} -> 1 | Q7: {=IFERROR( COUNTIFS(Attendance_data!$B$4:$B$1000,Q$4, INDIRECT("Attendance_data!" & ADDRESS(4, MATCH($B7, Attendance_data!$E$3:$BI$3, 0) + 4) & ":" & ADDRESS(1000, MATCH($B7, Attendance_data!$E$3:$BI$3, 0) + 4)), "P" ) / ( COUNTIFS( Attendance_data!$B$4:$B$1000,Q$4, INDIRECT("Attendance_data!" & ADDRESS(4, MATCH($B7, Attendance_data!$E$3:$BI$3, 0) + 4) & ":" & ADDRESS(1000, MATCH($B7, Attendance_data!$E$3:$BI$3, 0) + 4)), "P" ) + COUNTIFS( Attendance_data!$B$4:$B$1000,Q$4, INDIRECT("Attendance_data!" & ADDRESS(4, MATCH($B7, Attendance_data!$E$3:$BI$3, 0) + 4) & ":" & ADDRESS(1000, MATCH($B7, Attendance_data!$E$3:$BI$3, 0) + 4)), "A" ) ),"")} -> 0.69230769 | R7: {=IFERROR( COUNTIFS(Attendance_data!$B$4:$B$1000,R$4, INDIRECT("Attendance_data!" & ADDRESS(4, MATCH($B7, Attendance_data!$E$3:$BI$3, 0) + 4) & ":" & ADDRESS(1000, MATCH($B7, Attendance_data!$E$3:$BI$3, 0) + 4)), "P" ) / ( COUNTIFS( Attendance_data!$B$4:$B$1000,R$4, INDIRECT("Attendance_data!" & ADDRESS(4, MATCH($B7, Attendance_data!$E$3:$BI$3, 0) + 4) & ":" & ADDRESS(1000, MATCH($B7, Attendance_data!$E$3:$BI$3, 0) + 4)), "P" ) + COUNTIFS( Attendance_data!$B$4:$B$1000,R$4, INDIRECT("Attendance_data!" & ADDRESS(4, MATCH($B7, Attendance_data!$E$3:$BI$3, 0) + 4) & ":" & ADDRESS(1000, MATCH($B7, Attendance_data!$E$3:$BI$3, 0) + 4)), "A" ) ),"")} -> 0.89473684 | S7: {=IFERROR( COUNTIFS(Attendance_data!$B$4:$B$1000,S$4, INDIRECT("Attendance_data!" & ADDRESS(4, MATCH($B7, Attendance_data!$E$3:$BI$3, 0) + 4) & ":" & ADDRESS(1000, MATCH($B7, Attendance_data!$E$3:$BI$3, 0) + 4)), "P" ) / ( COUNTIFS( Attendance_data!$B$4:$B$1000,S$4, INDIRECT("Attendance_data!" & ADDRESS(4, MATCH($B7, Attendance_data!$E$3:$BI$3, 0) + 4) & ":" & ADDRESS(1000, MATCH($B7, Attendance_data!$E$3:$BI$3, 0) + 4)), "P" ) + COUNTIFS( Attendance_data!$B$4:$B$1000,S$4, INDIRECT("Attendance_data!" & ADDRESS(4, MATCH($B7, Attendance_data!$E$3:$BI$3, 0) + 4) & ":" & ADDRESS(1000, MATCH($B7, Attendance_data!$E$3:$BI$3, 0) + 4)), "A" ) ),"")} -> 0.77272727 | T7: {=IFERROR( COUNTIFS(Attendance_data!$B$4:$B$1000,T$4, INDIRECT("Attendance_data!" & ADDRESS(4, MATCH($B7, Attendance_data!$E$3:$BI$3, 0) + 4) & ":" & ADDRESS(1000, MATCH($B7, Attendance_data!$E$3:$BI$3, 0) + 4)), "P" ) / ( COUNTIFS( Attendance_data!$B$4:$B$1000,T$4, INDIRECT("Attendance_data!" & ADDRESS(4, MATCH($B7, Attendance_data!$E$3:$BI$3, 0) + 4) & ":" & ADDRESS(1000, MATCH($B7, Attendance_data!$E$3:$BI$3, 0) + 4)), "P" ) + COUNTIFS( Attendance_data!$B$4:$B$1000,T$4, INDIRECT("Attendance_data!" & ADDRESS(4, MATCH($B7, Attendance_data!$E$3:$BI$3, 0) + 4) & ":" & ADDRESS(1000, MATCH($B7, Attendance_data!$E$3:$BI$3, 0) + 4)), "A" ) ),"")} -> 0.75 | U7: {=IFERROR( COUNTIFS(Attendance_data!$B$4:$B$1000,U$4, INDIRECT("Attendance_data!" & ADDRESS(4, MATCH($B7, Attendance_data!$E$3:$BI$3, 0) + 4) & ":" & ADDRESS(1000, MATCH($B7, Attendance_data!$E$3:$BI$3, 0) + 4)), "P" ) / ( COUNTIFS( Attendance_data!$B$4:$B$1000,U$4, INDIRECT("Attendance_data!" & ADDRESS(4, MATCH($B7, Attendance_data!$E$3:$BI$3, 0) + 4) & ":" & ADDRESS(1000, MATCH($B7, Attendance_data!$E$3:$BI$3, 0) + 4)), "P" ) + COUNTIFS( Attendance_data!$B$4:$B$1000,U$4, INDIRECT("Attendance_data!" & ADDRESS(4, MATCH($B7, Attendance_data!$E$3:$BI$3, 0) + 4) & ":" & ADDRESS(1000, MATCH($B7, Attendance_data!$E$3:$BI$3, 0) + 4)), "A" ) ),"")} -> 0.84 | V7: {=IFERROR( COUNTIFS(Attendance_data!$B$4:$B$1000,V$4, INDIRECT("Attendance_data!" & ADDRESS(4, MATCH($B7, Attendance_data!$E$3:$BI$3, 0) + 4) & ":" & ADDRESS(1000, MATCH($B7, Attendance_data!$E$3:$BI$3, 0) + 4)), "P" ) / ( COUNTIFS( Attendance_data!$B$4:$B$1000,V$4, INDIRECT("Attendance_data!" & ADDRESS(4, MATCH($B7, Attendance_data!$E$3:$BI$3, 0) + 4) & ":" & ADDRESS(1000, MATCH($B7, Attendance_data!$E$3:$BI$3, 0) + 4)), "P" ) + COUNTIFS( Attendance_data!$B$4:$B$1000,V$4, INDIRECT("Attendance_data!" & ADDRESS(4, MATCH($B7, Attendance_data!$E$3:$BI$3, 0) + 4) & ":" & ADDRESS(1000, MATCH($B7, Attendance_data!$E$3:$BI$3, 0) + 4)), "A" ) ),"")} -> 0.88 | W7: {=IFERROR( COUNTIFS(Attendance_data!$B$4:$B$1000,W$4, INDIRECT("Attendance_data!" & ADDRESS(4, MATCH($B7, Attendance_data!$E$3:$BI$3, 0) + 4) & ":" & ADDRESS(1000, MATCH($B7, Attendance_data!$E$3:$BI$3, 0) + 4)), "P" ) / ( COUNTIFS( Attendance_data!$B$4:$B$1000,W$4, INDIRECT("Attendance_data!" & ADDRESS(4, MATCH($B7, Attendance_data!$E$3:$BI$3, 0) + 4) & ":" & ADDRESS(1000, MATCH($B7, Attendance_data!$E$3:$BI$3, 0) + 4)), "P" ) + COUNTIFS( Attendance_data!$B$4:$B$1000,W$4, INDIRECT("Attendance_data!" & ADDRESS(4, MATCH($B7, Attendance_data!$E$3:$BI$3, 0) + 4) & ":" & ADDRESS(1000, MATCH($B7, Attendance_data!$E$3:$BI$3, 0) + 4)), "A" ) ),"")} -> 0.92 | ... AA7: {=IFERROR( COUNTIFS(Attendance_data!$B$4:$B$1000,AA$4, INDIRECT("Attendance_data!" & ADDRESS(4, MATCH($B7, Attendance_data!$E$3:$BI$3, 0) + 4) & ":" & ADDRESS(1000, MATCH($B7, Attendance_data!$E$3:$BI$3, 0) + 4)), "P" ) / ( COUNTIFS( Attendance_data!$B$4:$B$1000,AA$4, INDIRECT("Attendance_data!" & ADDRESS(4, MATCH($B7, Attendance_data!$E$3:$BI$3, 0) + 4) & ":" & ADDRESS(1000, MATCH($B7, Attendance_data!$E$3:$BI$3, 0) + 4)), "P" ) + COUNTIFS( Attendance_data!$B$4:$B$1000,AA$4, INDIRECT("Attendance_data!" & ADDRESS(4, MATCH($B7, Attendance_data!$E$3:$BI$3, 0) + 4) & ":" & ADDRESS(1000, MATCH($B7, Attendance_data!$E$3:$BI$3, 0) + 4)), "A" ) ),"")} | AB7: =AVERAGEIF(P7:Z7,">0") -> 0.78271528
A8: =ROW()-4 -> 4 | B8: NMUD06 | C8: Ankita Ravindra Roy | D8: 10th | E8: Girl | F8: 9076021738 | G8: Reading and Writing | H8: 2016 | I8: Active | J8: 26 | K8: 23 | L8: 27 | M8: 27 | N8: 28 | O8: NA | P8: {=IFERROR( COUNTIFS(Attendance_data!$B$4:$B$1000,P$4, INDIRECT("Attendance_data!" & ADDRESS(4, MATCH($B8, Attendance_data!$E$3:$BI$3, 0) + 4) & ":" & ADDRESS(1000, MATCH($B8, Attendance_data!$E$3:$BI$3, 0) + 4)), "P" ) / ( COUNTIFS( Attendance_data!$B$4:$B$1000,P$4, INDIRECT("Attendance_data!" & ADDRESS(4, MATCH($B8, Attendance_data!$E$3:$BI$3, 0) + 4) & ":" & ADDRESS(1000, MATCH($B8, Attendance_data!$E$3:$BI$3, 0) + 4)), "P" ) + COUNTIFS( Attendance_data!$B$4:$B$1000,P$4, INDIRECT("Attendance_data!" & ADDRESS(4, MATCH($B8, Attendance_data!$E$3:$BI$3, 0) + 4) & ":" & ADDRESS(1000, MATCH($B8, Attendance_data!$E$3:$BI$3, 0) + 4)), "A" ) ),"")} -> 0.85714286 | Q8: {=IFERROR( COUNTIFS(Attendance_data!$B$4:$B$1000,Q$4, INDIRECT("Attendance_data!" & ADDRESS(4, MATCH($B8, Attendance_data!$E$3:$BI$3, 0) + 4) & ":" & ADDRESS(1000, MATCH($B8, Attendance_data!$E$3:$BI$3, 0) + 4)), "P" ) / ( COUNTIFS( Attendance_data!$B$4:$B$1000,Q$4, INDIRECT("Attendance_data!" & ADDRESS(4, MATCH($B8, Attendance_data!$E$3:$BI$3, 0) + 4) & ":" & ADDRESS(1000, MATCH($B8, Attendance_data!$E$3:$BI$3, 0) + 4)), "P" ) + COUNTIFS( Attendance_data!$B$4:$B$1000,Q$4, INDIRECT("Attendance_data!" & ADDRESS(4, MATCH($B8, Attendance_data!$E$3:$BI$3, 0) + 4) & ":" & ADDRESS(1000, MATCH($B8, Attendance_data!$E$3:$BI$3, 0) + 4)), "A" ) ),"")} -> 0.46153846 | R8: {=IFERROR( COUNTIFS(Attendance_data!$B$4:$B$1000,R$4, INDIRECT("Attendance_data!" & ADDRESS(4, MATCH($B8, Attendance_data!$E$3:$BI$3, 0) + 4) & ":" & ADDRESS(1000, MATCH($B8, Attendance_data!$E$3:$BI$3, 0) + 4)), "P" ) / ( COUNTIFS( Attendance_data!$B$4:$B$1000,R$4, INDIRECT("Attendance_data!" & ADDRESS(4, MATCH($B8, Attendance_data!$E$3:$BI$3, 0) + 4) & ":" & ADDRESS(1000, MATCH($B8, Attendance_data!$E$3:$BI$3, 0) + 4)), "P" ) + COUNTIFS( Attendance_data!$B$4:$B$1000,R$4, INDIRECT("Attendance_data!" & ADDRESS(4, MATCH($B8, Attendance_data!$E$3:$BI$3, 0) + 4) & ":" & ADDRESS(1000, MATCH($B8, Attendance_data!$E$3:$BI$3, 0) + 4)), "A" ) ),"")} -> 0.47368421 | S8: {=IFERROR( COUNTIFS(Attendance_data!$B$4:$B$1000,S$4, INDIRECT("Attendance_data!" & ADDRESS(4, MATCH($B8, Attendance_data!$E$3:$BI$3, 0) + 4) & ":" & ADDRESS(1000, MATCH($B8, Attendance_data!$E$3:$BI$3, 0) + 4)), "P" ) / ( COUNTIFS( Attendance_data!$B$4:$B$1000,S$4, INDIRECT("Attendance_data!" & ADDRESS(4, MATCH($B8, Attendance_data!$E$3:$BI$3, 0) + 4) & ":" & ADDRESS(1000, MATCH($B8, Attendance_data!$E$3:$BI$3, 0) + 4)), "P" ) + COUNTIFS( Attendance_data!$B$4:$B$1000,S$4, INDIRECT("Attendance_data!" & ADDRESS(4, MATCH($B8, Attendance_data!$E$3:$BI$3, 0) + 4) & ":" & ADDRESS(1000, MATCH($B8, Attendance_data!$E$3:$BI$3, 0) + 4)), "A" ) ),"")} -> 0.68181818 | T8: {=IFERROR( COUNTIFS(Attendance_data!$B$4:$B$1000,T$4, INDIRECT("Attendance_data!" & ADDRESS(4, MATCH($B8, Attendance_data!$E$3:$BI$3, 0) + 4) & ":" & ADDRESS(1000, MATCH($B8, Attendance_data!$E$3:$BI$3, 0) + 4)), "P" ) / ( COUNTIFS( Attendance_data!$B$4:$B$1000,T$4, INDIRECT("Attendance_data!" & ADDRESS(4, MATCH($B8, Attendance_data!$E$3:$BI$3, 0) + 4) & ":" & ADDRESS(1000, MATCH($B8, Attendance_data!$E$3:$BI$3, 0) + 4)), "P" ) + COUNTIFS( Attendance_data!$B$4:$B$1000,T$4, INDIRECT("Attendance_data!" & ADDRESS(4, MATCH($B8, Attendance_data!$E$3:$BI$3, 0) + 4) & ":" & ADDRESS(1000, MATCH($B8, Attendance_data!$E$3:$BI$3, 0) + 4)), "A" ) ),"")} -> 0.8 | U8: {=IFERROR( COUNTIFS(Attendance_data!$B$4:$B$1000,U$4, INDIRECT("Attendance_data!" & ADDRESS(4, MATCH($B8, Attendance_data!$E$3:$BI$3, 0) + 4) & ":" & ADDRESS(1000, MATCH($B8, Attendance_data!$E$3:$BI$3, 0) + 4)), "P" ) / ( COUNTIFS( Attendance_data!$B$4:$B$1000,U$4, INDIRECT("Attendance_data!" & ADDRESS(4, MATCH($B8, Attendance_data!$E$3:$BI$3, 0) + 4) & ":" & ADDRESS(1000, MATCH($B8, Attendance_data!$E$3:$BI$3, 0) + 4)), "P" ) + COUNTIFS( Attendance_data!$B$4:$B$1000,U$4, INDIRECT("Attendance_data!" & ADDRESS(4, MATCH($B8, Attendance_data!$E$3:$BI$3, 0) + 4) & ":" & ADDRESS(1000, MATCH($B8, Attendance_data!$E$3:$BI$3, 0) + 4)), "A" ) ),"")} -> 0.64 | V8: {=IFERROR( COUNTIFS(Attendance_data!$B$4:$B$1000,V$4, INDIRECT("Attendance_data!" & ADDRESS(4, MATCH($B8, Attendance_data!$E$3:$BI$3, 0) + 4) & ":" & ADDRESS(1000, MATCH($B8, Attendance_data!$E$3:$BI$3, 0) + 4)), "P" ) / ( COUNTIFS( Attendance_data!$B$4:$B$1000,V$4, INDIRECT("Attendance_data!" & ADDRESS(4, MATCH($B8, Attendance_data!$E$3:$BI$3, 0) + 4) & ":" & ADDRESS(1000, MATCH($B8, Attendance_data!$E$3:$BI$3, 0) + 4)), "P" ) + COUNTIFS( Attendance_data!$B$4:$B$1000,V$4, INDIRECT("Attendance_data!" & ADDRESS(4, MATCH($B8, Attendance_data!$E$3:$BI$3, 0) + 4) & ":" & ADDRESS(1000, MATCH($B8, Attendance_data!$E$3:$BI$3, 0) + 4)), "A" ) ),"")} -> 0.48 | W8: {=IFERROR( COUNTIFS(Attendance_data!$B$4:$B$1000,W$4, INDIRECT("Attendance_data!" & ADDRESS(4, MATCH($B8, Attendance_data!$E$3:$BI$3, 0) + 4) & ":" & ADDRESS(1000, MATCH($B8, Attendance_data!$E$3:$BI$3, 0) + 4)), "P" ) / ( COUNTIFS( Attendance_data!$B$4:$B$1000,W$4, INDIRECT("Attendance_data!" & ADDRESS(4, MATCH($B8, Attendance_data!$E$3:$BI$3, 0) + 4) & ":" & ADDRESS(1000, MATCH($B8, Attendance_data!$E$3:$BI$3, 0) + 4)), "P" ) + COUNTIFS( Attendance_data!$B$4:$B$1000,W$4, INDIRECT("Attendance_data!" & ADDRESS(4, MATCH($B8, Attendance_data!$E$3:$BI$3, 0) + 4) & ":" & ADDRESS(1000, MATCH($B8, Attendance_data!$E$3:$BI$3, 0) + 4)), "A" ) ),"")} -> 0.04 | ... AA8: {=IFERROR( COUNTIFS(Attendance_data!$B$4:$B$1000,AA$4, INDIRECT("Attendance_data!" & ADDRESS(4, MATCH($B8, Attendance_data!$E$3:$BI$3, 0) + 4) & ":" & ADDRESS(1000, MATCH($B8, Attendance_data!$E$3:$BI$3, 0) + 4)), "P" ) / ( COUNTIFS( Attendance_data!$B$4:$B$1000,AA$4, INDIRECT("Attendance_data!" & ADDRESS(4, MATCH($B8, Attendance_data!$E$3:$BI$3, 0) + 4) & ":" & ADDRESS(1000, MATCH($B8, Attendance_data!$E$3:$BI$3, 0) + 4)), "P" ) + COUNTIFS( Attendance_data!$B$4:$B$1000,AA$4, INDIRECT("Attendance_data!" & ADDRESS(4, MATCH($B8, Attendance_data!$E$3:$BI$3, 0) + 4) & ":" & ADDRESS(1000, MATCH($B8, Attendance_data!$E$3:$BI$3, 0) + 4)), "A" ) ),"")} | AB8: =AVERAGEIF(P8:Z8,">0") -> 0.4844898
A9: =ROW()-4 -> 5 | B9: NMUD08 | C9: Ashok Govinda Kanojiya | D9: 10th | E9: Boy | F9: 9769889782 | G9: Playing Kabaddi | H9: 2018 | I9: Active | J9: 26 | K9: 27 | L9: 27 | M9: 26 | N9: 29 | O9: NA | P9: {=IFERROR( COUNTIFS(Attendance_data!$B$4:$B$1000,P$4, INDIRECT("Attendance_data!" & ADDRESS(4, MATCH($B9, Attendance_data!$E$3:$BI$3, 0) + 4) & ":" & ADDRESS(1000, MATCH($B9, Attendance_data!$E$3:$BI$3, 0) + 4)), "P" ) / ( COUNTIFS( Attendance_data!$B$4:$B$1000,P$4, INDIRECT("Attendance_data!" & ADDRESS(4, MATCH($B9, Attendance_data!$E$3:$BI$3, 0) + 4) & ":" & ADDRESS(1000, MATCH($B9, Attendance_data!$E$3:$BI$3, 0) + 4)), "P" ) + COUNTIFS( Attendance_data!$B$4:$B$1000,P$4, INDIRECT("Attendance_data!" & ADDRESS(4, MATCH($B9, Attendance_data!$E$3:$BI$3, 0) + 4) & ":" & ADDRESS(1000, MATCH($B9, Attendance_data!$E$3:$BI$3, 0) + 4)), "A" ) ),"")} -> 1 | Q9: {=IFERROR( COUNTIFS(Attendance_data!$B$4:$B$1000,Q$4, INDIRECT("Attendance_data!" & ADDRESS(4, MATCH($B9, Attendance_data!$E$3:$BI$3, 0) + 4) & ":" & ADDRESS(1000, MATCH($B9, Attendance_data!$E$3:$BI$3, 0) + 4)), "P" ) / ( COUNTIFS( Attendance_data!$B$4:$B$1000,Q$4, INDIRECT("Attendance_data!" & ADDRESS(4, MATCH($B9, Attendance_data!$E$3:$BI$3, 0) + 4) & ":" & ADDRESS(1000, MATCH($B9, Attendance_data!$E$3:$BI$3, 0) + 4)), "P" ) + COUNTIFS( Attendance_data!$B$4:$B$1000,Q$4, INDIRECT("Attendance_data!" & ADDRESS(4, MATCH($B9, Attendance_data!$E$3:$BI$3, 0) + 4) & ":" & ADDRESS(1000, MATCH($B9, Attendance_data!$E$3:$BI$3, 0) + 4)), "A" ) ),"")} -> 0.96153846 | R9: {=IFERROR( COUNTIFS(Attendance_data!$B$4:$B$1000,R$4, INDIRECT("Attendance_data!" & ADDRESS(4, MATCH($B9, Attendance_data!$E$3:$BI$3, 0) + 4) & ":" & ADDRESS(1000, MATCH($B9, Attendance_data!$E$3:$BI$3, 0) + 4)), "P" ) / ( COUNTIFS( Attendance_data!$B$4:$B$1000,R$4, INDIRECT("Attendance_data!" & ADDRESS(4, MATCH($B9, Attendance_data!$E$3:$BI$3, 0) + 4) & ":" & ADDRESS(1000, MATCH($B9, Attendance_data!$E$3:$BI$3, 0) + 4)), "P" ) + COUNTIFS( Attendance_data!$B$4:$B$1000,R$4, INDIRECT("Attendance_data!" & ADDRESS(4, MATCH($B9, Attendance_data!$E$3:$BI$3, 0) + 4) & ":" & ADDRESS(1000, MATCH($B9, Attendance_data!$E$3:$BI$3, 0) + 4)), "A" ) ),"")} -> 0.94736842 | S9: {=IFERROR( COUNTIFS(Attendance_data!$B$4:$B$1000,S$4, INDIRECT("Attendance_data!" & ADDRESS(4, MATCH($B9, Attendance_data!$E$3:$BI$3, 0) + 4) & ":" & ADDRESS(1000, MATCH($B9, Attendance_data!$E$3:$BI$3, 0) + 4)), "P" ) / ( COUNTIFS( Attendance_data!$B$4:$B$1000,S$4, INDIRECT("Attendance_data!" & ADDRESS(4, MATCH($B9, Attendance_data!$E$3:$BI$3, 0) + 4) & ":" & ADDRESS(1000, MATCH($B9, Attendance_data!$E$3:$BI$3, 0) + 4)), "P" ) + COUNTIFS( Attendance_data!$B$4:$B$1000,S$4, INDIRECT("Attendance_data!" & ADDRESS(4, MATCH($B9, Attendance_data!$E$3:$BI$3, 0) + 4) & ":" & ADDRESS(1000, MATCH($B9, Attendance_data!$E$3:$BI$3, 0) + 4)), "A" ) ),"")} -> 1 | T9: {=IFERROR( COUNTIFS(Attendance_data!$B$4:$B$1000,T$4, INDIRECT("Attendance_data!" & ADDRESS(4, MATCH($B9, Attendance_data!$E$3:$BI$3, 0) + 4) & ":" & ADDRESS(1000, MATCH($B9, Attendance_data!$E$3:$BI$3, 0) + 4)), "P" ) / ( COUNTIFS( Attendance_data!$B$4:$B$1000,T$4, INDIRECT("Attendance_data!" & ADDRESS(4, MATCH($B9, Attendance_data!$E$3:$BI$3, 0) + 4) & ":" & ADDRESS(1000, MATCH($B9, Attendance_data!$E$3:$BI$3, 0) + 4)), "P" ) + COUNTIFS( Attendance_data!$B$4:$B$1000,T$4, INDIRECT("Attendance_data!" & ADDRESS(4, MATCH($B9, Attendance_data!$E$3:$BI$3, 0) + 4) & ":" & ADDRESS(1000, MATCH($B9, Attendance_data!$E$3:$BI$3, 0) + 4)), "A" ) ),"")} -> 0.95 | U9: {=IFERROR( COUNTIFS(Attendance_data!$B$4:$B$1000,U$4, INDIRECT("Attendance_data!" & ADDRESS(4, MATCH($B9, Attendance_data!$E$3:$BI$3, 0) + 4) & ":" & ADDRESS(1000, MATCH($B9, Attendance_data!$E$3:$BI$3, 0) + 4)), "P" ) / ( COUNTIFS( Attendance_data!$B$4:$B$1000,U$4, INDIRECT("Attendance_data!" & ADDRESS(4, MATCH($B9, Attendance_data!$E$3:$BI$3, 0) + 4) & ":" & ADDRESS(1000, MATCH($B9, Attendance_data!$E$3:$BI$3, 0) + 4)), "P" ) + COUNTIFS( Attendance_data!$B$4:$B$1000,U$4, INDIRECT("Attendance_data!" & ADDRESS(4, MATCH($B9, Attendance_data!$E$3:$BI$3, 0) + 4) & ":" & ADDRESS(1000, MATCH($B9, Attendance_data!$E$3:$BI$3, 0) + 4)), "A" ) ),"")} -> 1 | V9: {=IFERROR( COUNTIFS(Attendance_data!$B$4:$B$1000,V$4, INDIRECT("Attendance_data!" & ADDRESS(4, MATCH($B9, Attendance_data!$E$3:$BI$3, 0) + 4) & ":" & ADDRESS(1000, MATCH($B9, Attendance_data!$E$3:$BI$3, 0) + 4)), "P" ) / ( COUNTIFS( Attendance_data!$B$4:$B$1000,V$4, INDIRECT("Attendance_data!" & ADDRESS(4, MATCH($B9, Attendance_data!$E$3:$BI$3, 0) + 4) & ":" & ADDRESS(1000, MATCH($B9, Attendance_data!$E$3:$BI$3, 0) + 4)), "P" ) + COUNTIFS( Attendance_data!$B$4:$B$1000,V$4, INDIRECT("Attendance_data!" & ADDRESS(4, MATCH($B9, Attendance_data!$E$3:$BI$3, 0) + 4) & ":" & ADDRESS(1000, MATCH($B9, Attendance_data!$E$3:$BI$3, 0) + 4)), "A" ) ),"")} -> 1 | W9: {=IFERROR( COUNTIFS(Attendance_data!$B$4:$B$1000,W$4, INDIRECT("Attendance_data!" & ADDRESS(4, MATCH($B9, Attendance_data!$E$3:$BI$3, 0) + 4) & ":" & ADDRESS(1000, MATCH($B9, Attendance_data!$E$3:$BI$3, 0) + 4)), "P" ) / ( COUNTIFS( Attendance_data!$B$4:$B$1000,W$4, INDIRECT("Attendance_data!" & ADDRESS(4, MATCH($B9, Attendance_data!$E$3:$BI$3, 0) + 4) & ":" & ADDRESS(1000, MATCH($B9, Attendance_data!$E$3:$BI$3, 0) + 4)), "P" ) + COUNTIFS( Attendance_data!$B$4:$B$1000,W$4, INDIRECT("Attendance_data!" & ADDRESS(4, MATCH($B9, Attendance_data!$E$3:$BI$3, 0) + 4) & ":" & ADDRESS(1000, MATCH($B9, Attendance_data!$E$3:$BI$3, 0) + 4)), "A" ) ),"")} -> 1 | ... AA9: {=IFERROR( COUNTIFS(Attendance_data!$B$4:$B$1000,AA$4, INDIRECT("Attendance_data!" & ADDRESS(4, MATCH($B9, Attendance_data!$E$3:$BI$3, 0) + 4) & ":" & ADDRESS(1000, MATCH($B9, Attendance_data!$E$3:$BI$3, 0) + 4)), "P" ) / ( COUNTIFS( Attendance_data!$B$4:$B$1000,AA$4, INDIRECT("Attendance_data!" & ADDRESS(4, MATCH($B9, Attendance_data!$E$3:$BI$3, 0) + 4) & ":" & ADDRESS(1000, MATCH($B9, Attendance_data!$E$3:$BI$3, 0) + 4)), "P" ) + COUNTIFS( Attendance_data!$B$4:$B$1000,AA$4, INDIRECT("Attendance_data!" & ADDRESS(4, MATCH($B9, Attendance_data!$E$3:$BI$3, 0) + 4) & ":" & ADDRESS(1000, MATCH($B9, Attendance_data!$E$3:$BI$3, 0) + 4)), "A" ) ),"")} | AB9: =AVERAGEIF(P9:Z9,">0") -> 0.85586022
A10: =ROW()-4 -> 6 | B10: NMUD28 | C10: Soham anil waghmare | D10: 9th | E10: Boy | F10: 8591911057 | G10: Playing Kabaddi | H10: 2020 | I10: Active | J10: 19 | K10: 25 | L10: 28 | M10: 27 | N10: 28 | O10: 21 | P10: {=IFERROR( COUNTIFS(Attendance_data!$B$4:$B$1000,P$4, INDIRECT("Attendance_data!" & ADDRESS(4, MATCH($B10, Attendance_data!$E$3:$BI$3, 0) + 4) & ":" & ADDRESS(1000, MATCH($B10, Attendance_data!$E$3:$BI$3, 0) + 4)), "P" ) / ( COUNTIFS( Attendance_data!$B$4:$B$1000,P$4, INDIRECT("Attendance_data!" & ADDRESS(4, MATCH($B10, Attendance_data!$E$3:$BI$3, 0) + 4) & ":" & ADDRESS(1000, MATCH($B10, Attendance_data!$E$3:$BI$3, 0) + 4)), "P" ) + COUNTIFS( Attendance_data!$B$4:$B$1000,P$4, INDIRECT("Attendance_data!" & ADDRESS(4, MATCH($B10, Attendance_data!$E$3:$BI$3, 0) + 4) & ":" & ADDRESS(1000, MATCH($B10, Attendance_data!$E$3:$BI$3, 0) + 4)), "A" ) ),"")} -> 0.95238095 | Q10: {=IFERROR( COUNTIFS(Attendance_data!$B$4:$B$1000,Q$4, INDIRECT("Attendance_data!" & ADDRESS(4, MATCH($B10, Attendance_data!$E$3:$BI$3, 0) + 4) & ":" & ADDRESS(1000, MATCH($B10, Attendance_data!$E$3:$BI$3, 0) + 4)), "P" ) / ( COUNTIFS( Attendance_data!$B$4:$B$1000,Q$4, INDIRECT("Attendance_data!" & ADDRESS(4, MATCH($B10, Attendance_data!$E$3:$BI$3, 0) + 4) & ":" & ADDRESS(1000, MATCH($B10, Attendance_data!$E$3:$BI$3, 0) + 4)), "P" ) + COUNTIFS( Attendance_data!$B$4:$B$1000,Q$4, INDIRECT("Attendance_data!" & ADDRESS(4, MATCH($B10, Attendance_data!$E$3:$BI$3, 0) + 4) & ":" & ADDRESS(1000, MATCH($B10, Attendance_data!$E$3:$BI$3, 0) + 4)), "A" ) ),"")} -> 0.73076923 | R10: {=IFERROR( COUNTIFS(Attendance_data!$B$4:$B$1000,R$4, INDIRECT("Attendance_data!" & ADDRESS(4, MATCH($B10, Attendance_data!$E$3:$BI$3, 0) + 4) & ":" & ADDRESS(1000, MATCH($B10, Attendance_data!$E$3:$BI$3, 0) + 4)), "P" ) / ( COUNTIFS( Attendance_data!$B$4:$B$1000,R$4, INDIRECT("Attendance_data!" & ADDRESS(4, MATCH($B10, Attendance_data!$E$3:$BI$3, 0) + 4) & ":" & ADDRESS(1000, MATCH($B10, Attendance_data!$E$3:$BI$3, 0) + 4)), "P" ) + COUNTIFS( Attendance_data!$B$4:$B$1000,R$4, INDIRECT("Attendance_data!" & ADDRESS(4, MATCH($B10, Attendance_data!$E$3:$BI$3, 0) + 4) & ":" & ADDRESS(1000, MATCH($B10, Attendance_data!$E$3:$BI$3, 0) + 4)), "A" ) ),"")} -> 0.78947368 | S10: {=IFERROR( COUNTIFS(Attendance_data!$B$4:$B$1000,S$4, INDIRECT("Attendance_data!" & ADDRESS(4, MATCH($B10, Attendance_data!$E$3:$BI$3, 0) + 4) & ":" & ADDRESS(1000, MATCH($B10, Attendance_data!$E$3:$BI$3, 0) + 4)), "P" ) / ( COUNTIFS( Attendance_data!$B$4:$B$1000,S$4, INDIRECT("Attendance_data!" & ADDRESS(4, MATCH($B10, Attendance_data!$E$3:$BI$3, 0) + 4) & ":" & ADDRESS(1000, MATCH($B10, Attendance_data!$E$3:$BI$3, 0) + 4)), "P" ) + COUNTIFS( Attendance_data!$B$4:$B$1000,S$4, INDIRECT("Attendance_data!" & ADDRESS(4, MATCH($B10, Attendance_data!$E$3:$BI$3, 0) + 4) & ":" & ADDRESS(1000, MATCH($B10, Attendance_data!$E$3:$BI$3, 0) + 4)), "A" ) ),"")} -> 0.72727273 | T10: {=IFERROR( COUNTIFS(Attendance_data!$B$4:$B$1000,T$4, INDIRECT("Attendance_data!" & ADDRESS(4, MATCH($B10, Attendance_data!$E$3:$BI$3, 0) + 4) & ":" & ADDRESS(1000, MATCH($B10, Attendance_data!$E$3:$BI$3, 0) + 4)), "P" ) / ( COUNTIFS( Attendance_data!$B$4:$B$1000,T$4, INDIRECT("Attendance_data!" & ADDRESS(4, MATCH($B10, Attendance_data!$E$3:$BI$3, 0) + 4) & ":" & ADDRESS(1000, MATCH($B10, Attendance_data!$E$3:$BI$3, 0) + 4)), "P" ) + COUNTIFS( Attendance_data!$B$4:$B$1000,T$4, INDIRECT("Attendance_data!" & ADDRESS(4, MATCH($B10, Attendance_data!$E$3:$BI$3, 0) + 4) & ":" & ADDRESS(1000, MATCH($B10, Attendance_data!$E$3:$BI$3, 0) + 4)), "A" ) ),"")} -> 0.9 | U10: {=IFERROR( COUNTIFS(Attendance_data!$B$4:$B$1000,U$4, INDIRECT("Attendance_data!" & ADDRESS(4, MATCH($B10, Attendance_data!$E$3:$BI$3, 0) + 4) & ":" & ADDRESS(1000, MATCH($B10, Attendance_data!$E$3:$BI$3, 0) + 4)), "P" ) / ( COUNTIFS( Attendance_data!$B$4:$B$1000,U$4, INDIRECT("Attendance_data!" & ADDRESS(4, MATCH($B10, Attendance_data!$E$3:$BI$3, 0) + 4) & ":" & ADDRESS(1000, MATCH($B10, Attendance_data!$E$3:$BI$3, 0) + 4)), "P" ) + COUNTIFS( Attendance_data!$B$4:$B$1000,U$4, INDIRECT("Attendance_data!" & ADDRESS(4, MATCH($B10, Attendance_data!$E$3:$BI$3, 0) + 4) & ":" & ADDRESS(1000, MATCH($B10, Attendance_data!$E$3:$BI$3, 0) + 4)), "A" ) ),"")} -> 0.92 | V10: {=IFERROR( COUNTIFS(Attendance_data!$B$4:$B$1000,V$4, INDIRECT("Attendance_data!" & ADDRESS(4, MATCH($B10, Attendance_data!$E$3:$BI$3, 0) + 4) & ":" & ADDRESS(1000, MATCH($B10, Attendance_data!$E$3:$BI$3, 0) + 4)), "P" ) / ( COUNTIFS( Attendance_data!$B$4:$B$1000,V$4, INDIRECT("Attendance_data!" & ADDRESS(4, MATCH($B10, Attendance_data!$E$3:$BI$3, 0) + 4) & ":" & ADDRESS(1000, MATCH($B10, Attendance_data!$E$3:$BI$3, 0) + 4)), "P" ) + COUNTIFS( Attendance_data!$B$4:$B$1000,V$4, INDIRECT("Attendance_data!" & ADDRESS(4, MATCH($B10, Attendance_data!$E$3:$BI$3, 0) + 4) & ":" & ADDRESS(1000, MATCH($B10, Attendance_data!$E$3:$BI$3, 0) + 4)), "A" ) ),"")} -> 0.84 | W10: {=IFERROR( COUNTIFS(Attendance_data!$B$4:$B$1000,W$4, INDIRECT("Attendance_data!" & ADDRESS(4, MATCH($B10, Attendance_data!$E$3:$BI$3, 0) + 4) & ":" & ADDRESS(1000, MATCH($B10, Attendance_data!$E$3:$BI$3, 0) + 4)), "P" ) / ( COUNTIFS( Attendance_data!$B$4:$B$1000,W$4, INDIRECT("Attendance_data!" & ADDRESS(4, MATCH($B10, Attendance_data!$E$3:$BI$3, 0) + 4) & ":" & ADDRESS(1000, MATCH($B10, Attendance_data!$E$3:$BI$3, 0) + 4)), "P" ) + COUNTIFS( Attendance_data!$B$4:$B$1000,W$4, INDIRECT("Attendance_data!" & ADDRESS(4, MATCH($B10, Attendance_data!$E$3:$BI$3, 0) + 4) & ":" & ADDRESS(1000, MATCH($B10, Attendance_data!$E$3:$BI$3, 0) + 4)), "A" ) ),"")} -> 0.88 | ... AA10: {=IFERROR( COUNTIFS(Attendance_data!$B$4:$B$1000,AA$4, INDIRECT("Attendance_data!" & ADDRESS(4, MATCH($B10, Attendance_data!$E$3:$BI$3, 0) + 4) & ":" & ADDRESS(1000, MATCH($B10, Attendance_data!$E$3:$BI$3, 0) + 4)), "P" ) / ( COUNTIFS( Attendance_data!$B$4:$B$1000,AA$4, INDIRECT("Attendance_data!" & ADDRESS(4, MATCH($B10, Attendance_data!$E$3:$BI$3, 0) + 4) & ":" & ADDRESS(1000, MATCH($B10, Attendance_data!$E$3:$BI$3, 0) + 4)), "P" ) + COUNTIFS( Attendance_data!$B$4:$B$1000,AA$4, INDIRECT("Attendance_data!" & ADDRESS(4, MATCH($B10, Attendance_data!$E$3:$BI$3, 0) + 4) & ":" & ADDRESS(1000, MATCH($B10, Attendance_data!$E$3:$BI$3, 0) + 4)), "A" ) ),"")} | AB10: =AVERAGEIF(P10:Z10,">0") -> 0.83205409
A11: =ROW()-4 -> 7 | B11: NMUD29 | C11: Subodh Ravi Hatkar | D11: 10th | E11: Boy | F11: 8850444041 | G11: Drawing | H11: 2021 | I11: Active | J11: 23 | K11: 28 | L11: 27 | M11: 25 | N11: 12 | O11: 20 | P11: {=IFERROR( COUNTIFS(Attendance_data!$B$4:$B$1000,P$4, INDIRECT("Attendance_data!" & ADDRESS(4, MATCH($B11, Attendance_data!$E$3:$BI$3, 0) + 4) & ":" & ADDRESS(1000, MATCH($B11, Attendance_data!$E$3:$BI$3, 0) + 4)), "P" ) / ( COUNTIFS( Attendance_data!$B$4:$B$1000,P$4, INDIRECT("Attendance_data!" & ADDRESS(4, MATCH($B11, Attendance_data!$E$3:$BI$3, 0) + 4) & ":" & ADDRESS(1000, MATCH($B11, Attendance_data!$E$3:$BI$3, 0) + 4)), "P" ) + COUNTIFS( Attendance_data!$B$4:$B$1000,P$4, INDIRECT("Attendance_data!" & ADDRESS(4, MATCH($B11, Attendance_data!$E$3:$BI$3, 0) + 4) & ":" & ADDRESS(1000, MATCH($B11, Attendance_data!$E$3:$BI$3, 0) + 4)), "A" ) ),"")} -> 1 | Q11: {=IFERROR( COUNTIFS(Attendance_data!$B$4:$B$1000,Q$4, INDIRECT("Attendance_data!" & ADDRESS(4, MATCH($B11, Attendance_data!$E$3:$BI$3, 0) + 4) & ":" & ADDRESS(1000, MATCH($B11, Attendance_data!$E$3:$BI$3, 0) + 4)), "P" ) / ( COUNTIFS( Attendance_data!$B$4:$B$1000,Q$4, INDIRECT("Attendance_data!" & ADDRESS(4, MATCH($B11, Attendance_data!$E$3:$BI$3, 0) + 4) & ":" & ADDRESS(1000, MATCH($B11, Attendance_data!$E$3:$BI$3, 0) + 4)), "P" ) + COUNTIFS( Attendance_data!$B$4:$B$1000,Q$4, INDIRECT("Attendance_data!" & ADDRESS(4, MATCH($B11, Attendance_data!$E$3:$BI$3, 0) + 4) & ":" & ADDRESS(1000, MATCH($B11, Attendance_data!$E$3:$BI$3, 0) + 4)), "A" ) ),"")} -> 0.84615385 | R11: {=IFERROR( COUNTIFS(Attendance_data!$B$4:$B$1000,R$4, INDIRECT("Attendance_data!" & ADDRESS(4, MATCH($B11, Attendance_data!$E$3:$BI$3, 0) + 4) & ":" & ADDRESS(1000, MATCH($B11, Attendance_data!$E$3:$BI$3, 0) + 4)), "P" ) / ( COUNTIFS( Attendance_data!$B$4:$B$1000,R$4, INDIRECT("Attendance_data!" & ADDRESS(4, MATCH($B11, Attendance_data!$E$3:$BI$3, 0) + 4) & ":" & ADDRESS(1000, MATCH($B11, Attendance_data!$E$3:$BI$3, 0) + 4)), "P" ) + COUNTIFS( Attendance_data!$B$4:$B$1000,R$4, INDIRECT("Attendance_data!" & ADDRESS(4, MATCH($B11, Attendance_data!$E$3:$BI$3, 0) + 4) & ":" & ADDRESS(1000, MATCH($B11, Attendance_data!$E$3:$BI$3, 0) + 4)), "A" ) ),"")} -> 1 | S11: {=IFERROR( COUNTIFS(Attendance_data!$B$4:$B$1000,S$4, INDIRECT("Attendance_data!" & ADDRESS(4, MATCH($B11, Attendance_data!$E$3:$BI$3, 0) + 4) & ":" & ADDRESS(1000, MATCH($B11, Attendance_data!$E$3:$BI$3, 0) + 4)), "P" ) / ( COUNTIFS( Attendance_data!$B$4:$B$1000,S$4, INDIRECT("Attendance_data!" & ADDRESS(4, MATCH($B11, Attendance_data!$E$3:$BI$3, 0) + 4) & ":" & ADDRESS(1000, MATCH($B11, Attendance_data!$E$3:$BI$3, 0) + 4)), "P" ) + COUNTIFS( Attendance_data!$B$4:$B$1000,S$4, INDIRECT("Attendance_data!" & ADDRESS(4, MATCH($B11, Attendance_data!$E$3:$BI$3, 0) + 4) & ":" & ADDRESS(1000, MATCH($B11, Attendance_data!$E$3:$BI$3, 0) + 4)), "A" ) ),"")} -> 1 | T11: {=IFERROR( COUNTIFS(Attendance_data!$B$4:$B$1000,T$4, INDIRECT("Attendance_data!" & ADDRESS(4, MATCH($B11, Attendance_data!$E$3:$BI$3, 0) + 4) & ":" & ADDRESS(1000, MATCH($B11, Attendance_data!$E$3:$BI$3, 0) + 4)), "P" ) / ( COUNTIFS( Attendance_data!$B$4:$B$1000,T$4, INDIRECT("Attendance_data!" & ADDRESS(4, MATCH($B11, Attendance_data!$E$3:$BI$3, 0) + 4) & ":" & ADDRESS(1000, MATCH($B11, Attendance_data!$E$3:$BI$3, 0) + 4)), "P" ) + COUNTIFS( Attendance_data!$B$4:$B$1000,T$4, INDIRECT("Attendance_data!" & ADDRESS(4, MATCH($B11, Attendance_data!$E$3:$BI$3, 0) + 4) & ":" & ADDRESS(1000, MATCH($B11, Attendance_data!$E$3:$BI$3, 0) + 4)), "A" ) ),"")} -> 1 | U11: {=IFERROR( COUNTIFS(Attendance_data!$B$4:$B$1000,U$4, INDIRECT("Attendance_data!" & ADDRESS(4, MATCH($B11, Attendance_data!$E$3:$BI$3, 0) + 4) & ":" & ADDRESS(1000, MATCH($B11, Attendance_data!$E$3:$BI$3, 0) + 4)), "P" ) / ( COUNTIFS( Attendance_data!$B$4:$B$1000,U$4, INDIRECT("Attendance_data!" & ADDRESS(4, MATCH($B11, Attendance_data!$E$3:$BI$3, 0) + 4) & ":" & ADDRESS(1000, MATCH($B11, Attendance_data!$E$3:$BI$3, 0) + 4)), "P" ) + COUNTIFS( Attendance_data!$B$4:$B$1000,U$4, INDIRECT("Attendance_data!" & ADDRESS(4, MATCH($B11, Attendance_data!$E$3:$BI$3, 0) + 4) & ":" & ADDRESS(1000, MATCH($B11, Attendance_data!$E$3:$BI$3, 0) + 4)), "A" ) ),"")} -> 0.96 | V11: {=IFERROR( COUNTIFS(Attendance_data!$B$4:$B$1000,V$4, INDIRECT("Attendance_data!" & ADDRESS(4, MATCH($B11, Attendance_data!$E$3:$BI$3, 0) + 4) & ":" & ADDRESS(1000, MATCH($B11, Attendance_data!$E$3:$BI$3, 0) + 4)), "P" ) / ( COUNTIFS( Attendance_data!$B$4:$B$1000,V$4, INDIRECT("Attendance_data!" & ADDRESS(4, MATCH($B11, Attendance_data!$E$3:$BI$3, 0) + 4) & ":" & ADDRESS(1000, MATCH($B11, Attendance_data!$E$3:$BI$3, 0) + 4)), "P" ) + COUNTIFS( Attendance_data!$B$4:$B$1000,V$4, INDIRECT("Attendance_data!" & ADDRESS(4, MATCH($B11, Attendance_data!$E$3:$BI$3, 0) + 4) & ":" & ADDRESS(1000, MATCH($B11, Attendance_data!$E$3:$BI$3, 0) + 4)), "A" ) ),"")} -> 0.96 | W11: {=IFERROR( COUNTIFS(Attendance_data!$B$4:$B$1000,W$4, INDIRECT("Attendance_data!" & ADDRESS(4, MATCH($B11, Attendance_data!$E$3:$BI$3, 0) + 4) & ":" & ADDRESS(1000, MATCH($B11, Attendance_data!$E$3:$BI$3, 0) + 4)), "P" ) / ( COUNTIFS( Attendance_data!$B$4:$B$1000,W$4, INDIRECT("Attendance_data!" & ADDRESS(4, MATCH($B11, Attendance_data!$E$3:$BI$3, 0) + 4) & ":" & ADDRESS(1000, MATCH($B11, Attendance_data!$E$3:$BI$3, 0) + 4)), "P" ) + COUNTIFS( Attendance_data!$B$4:$B$1000,W$4, INDIRECT("Attendance_data!" & ADDRESS(4, MATCH($B11, Attendance_data!$E$3:$BI$3, 0) + 4) & ":" & ADDRESS(1000, MATCH($B11, Attendance_data!$E$3:$BI$3, 0) + 4)), "A" ) ),"")} -> 1 | ... AA11: {=IFERROR( COUNTIFS(Attendance_data!$B$4:$B$1000,AA$4, INDIRECT("Attendance_data!" & ADDRESS(4, MATCH($B11, Attendance_data!$E$3:$BI$3, 0) + 4) & ":" & ADDRESS(1000, MATCH($B11, Attendance_data!$E$3:$BI$3, 0) + 4)), "P" ) / ( COUNTIFS( Attendance_data!$B$4:$B$1000,AA$4, INDIRECT("Attendance_data!" & ADDRESS(4, MATCH($B11, Attendance_data!$E$3:$BI$3, 0) + 4) & ":" & ADDRESS(1000, MATCH($B11, Attendance_data!$E$3:$BI$3, 0) + 4)), "P" ) + COUNTIFS( Attendance_data!$B$4:$B$1000,AA$4, INDIRECT("Attendance_data!" & ADDRESS(4, MATCH($B11, Attendance_data!$E$3:$BI$3, 0) + 4) & ":" & ADDRESS(1000, MATCH($B11, Attendance_data!$E$3:$BI$3, 0) + 4)), "A" ) ),"")} | AB11: =AVERAGEIF(P11:Z11,">0") -> 0.97874126
A12: =ROW()-4 -> 8 | B12: NMUD30 | C12: Mohini Bansraj Kanojiya | D12: 10th | E12: Girl | F12: 9619701755 | G12: Reading | H12: 2019 | I12: Active | J12: 28 | K12: 28 | L12: 30 | M12: 27 | N12: 30 | O12: NA | P12: {=IFERROR( COUNTIFS(Attendance_data!$B$4:$B$1000,P$4, INDIRECT("Attendance_data!" & ADDRESS(4, MATCH($B12, Attendance_data!$E$3:$BI$3, 0) + 4) & ":" & ADDRESS(1000, MATCH($B12, Attendance_data!$E$3:$BI$3, 0) + 4)), "P" ) / ( COUNTIFS( Attendance_data!$B$4:$B$1000,P$4, INDIRECT("Attendance_data!" & ADDRESS(4, MATCH($B12, Attendance_data!$E$3:$BI$3, 0) + 4) & ":" & ADDRESS(1000, MATCH($B12, Attendance_data!$E$3:$BI$3, 0) + 4)), "P" ) + COUNTIFS( Attendance_data!$B$4:$B$1000,P$4, INDIRECT("Attendance_data!" & ADDRESS(4, MATCH($B12, Attendance_data!$E$3:$BI$3, 0) + 4) & ":" & ADDRESS(1000, MATCH($B12, Attendance_data!$E$3:$BI$3, 0) + 4)), "A" ) ),"")} -> 0.95238095 | Q12: {=IFERROR( COUNTIFS(Attendance_data!$B$4:$B$1000,Q$4, INDIRECT("Attendance_data!" & ADDRESS(4, MATCH($B12, Attendance_data!$E$3:$BI$3, 0) + 4) & ":" & ADDRESS(1000, MATCH($B12, Attendance_data!$E$3:$BI$3, 0) + 4)), "P" ) / ( COUNTIFS( Attendance_data!$B$4:$B$1000,Q$4, INDIRECT("Attendance_data!" & ADDRESS(4, MATCH($B12, Attendance_data!$E$3:$BI$3, 0) + 4) & ":" & ADDRESS(1000, MATCH($B12, Attendance_data!$E$3:$BI$3, 0) + 4)), "P" ) + COUNTIFS( Attendance_data!$B$4:$B$1000,Q$4, INDIRECT("Attendance_data!" & ADDRESS(4, MATCH($B12, Attendance_data!$E$3:$BI$3, 0) + 4) & ":" & ADDRESS(1000, MATCH($B12, Attendance_data!$E$3:$BI$3, 0) + 4)), "A" ) ),"")} -> 0.84615385 | R12: {=IFERROR( COUNTIFS(Attendance_data!$B$4:$B$1000,R$4, INDIRECT("Attendance_data!" & ADDRESS(4, MATCH($B12, Attendance_data!$E$3:$BI$3, 0) + 4) & ":" & ADDRESS(1000, MATCH($B12, Attendance_data!$E$3:$BI$3, 0) + 4)), "P" ) / ( COUNTIFS( Attendance_data!$B$4:$B$1000,R$4, INDIRECT("Attendance_data!" & ADDRESS(4, MATCH($B12, Attendance_data!$E$3:$BI$3, 0) + 4) & ":" & ADDRESS(1000, MATCH($B12, Attendance_data!$E$3:$BI$3, 0) + 4)), "P" ) + COUNTIFS( Attendance_data!$B$4:$B$1000,R$4, INDIRECT("Attendance_data!" & ADDRESS(4, MATCH($B12, Attendance_data!$E$3:$BI$3, 0) + 4) & ":" & ADDRESS(1000, MATCH($B12, Attendance_data!$E$3:$BI$3, 0) + 4)), "A" ) ),"")} -> 0.94736842 | S12: {=IFERROR( COUNTIFS(Attendance_data!$B$4:$B$1000,S$4, INDIRECT("Attendance_data!" & ADDRESS(4, MATCH($B12, Attendance_data!$E$3:$BI$3, 0) + 4) & ":" & ADDRESS(1000, MATCH($B12, Attendance_data!$E$3:$BI$3, 0) + 4)), "P" ) / ( COUNTIFS( Attendance_data!$B$4:$B$1000,S$4, INDIRECT("Attendance_data!" & ADDRESS(4, MATCH($B12, Attendance_data!$E$3:$BI$3, 0) + 4) & ":" & ADDRESS(1000, MATCH($B12, Attendance_data!$E$3:$BI$3, 0) + 4)), "P" ) + COUNTIFS( Attendance_data!$B$4:$B$1000,S$4, INDIRECT("Attendance_data!" & ADDRESS(4, MATCH($B12, Attendance_data!$E$3:$BI$3, 0) + 4) & ":" & ADDRESS(1000, MATCH($B12, Attendance_data!$E$3:$BI$3, 0) + 4)), "A" ) ),"")} -> 0.77272727 | T12: {=IFERROR( COUNTIFS(Attendance_data!$B$4:$B$1000,T$4, INDIRECT("Attendance_data!" & ADDRESS(4, MATCH($B12, Attendance_data!$E$3:$BI$3, 0) + 4) & ":" & ADDRESS(1000, MATCH($B12, Attendance_data!$E$3:$BI$3, 0) + 4)), "P" ) / ( COUNTIFS( Attendance_data!$B$4:$B$1000,T$4, INDIRECT("Attendance_data!" & ADDRESS(4, MATCH($B12, Attendance_data!$E$3:$BI$3, 0) + 4) & ":" & ADDRESS(1000, MATCH($B12, Attendance_data!$E$3:$BI$3, 0) + 4)), "P" ) + COUNTIFS( Attendance_data!$B$4:$B$1000,T$4, INDIRECT("Attendance_data!" & ADDRESS(4, MATCH($B12, Attendance_data!$E$3:$BI$3, 0) + 4) & ":" & ADDRESS(1000, MATCH($B12, Attendance_data!$E$3:$BI$3, 0) + 4)), "A" ) ),"")} -> 0.8 | U12: {=IFERROR( COUNTIFS(Attendance_data!$B$4:$B$1000,U$4, INDIRECT("Attendance_data!" & ADDRESS(4, MATCH($B12, Attendance_data!$E$3:$BI$3, 0) + 4) & ":" & ADDRESS(1000, MATCH($B12, Attendance_data!$E$3:$BI$3, 0) + 4)), "P" ) / ( COUNTIFS( Attendance_data!$B$4:$B$1000,U$4, INDIRECT("Attendance_data!" & ADDRESS(4, MATCH($B12, Attendance_data!$E$3:$BI$3, 0) + 4) & ":" & ADDRESS(1000, MATCH($B12, Attendance_data!$E$3:$BI$3, 0) + 4)), "P" ) + COUNTIFS( Attendance_data!$B$4:$B$1000,U$4, INDIRECT("Attendance_data!" & ADDRESS(4, MATCH($B12, Attendance_data!$E$3:$BI$3, 0) + 4) & ":" & ADDRESS(1000, MATCH($B12, Attendance_data!$E$3:$BI$3, 0) + 4)), "A" ) ),"")} -> 0.44 | V12: {=IFERROR( COUNTIFS(Attendance_data!$B$4:$B$1000,V$4, INDIRECT("Attendance_data!" & ADDRESS(4, MATCH($B12, Attendance_data!$E$3:$BI$3, 0) + 4) & ":" & ADDRESS(1000, MATCH($B12, Attendance_data!$E$3:$BI$3, 0) + 4)), "P" ) / ( COUNTIFS( Attendance_data!$B$4:$B$1000,V$4, INDIRECT("Attendance_data!" & ADDRESS(4, MATCH($B12, Attendance_data!$E$3:$BI$3, 0) + 4) & ":" & ADDRESS(1000, MATCH($B12, Attendance_data!$E$3:$BI$3, 0) + 4)), "P" ) + COUNTIFS( Attendance_data!$B$4:$B$1000,V$4, INDIRECT("Attendance_data!" & ADDRESS(4, MATCH($B12, Attendance_data!$E$3:$BI$3, 0) + 4) & ":" & ADDRESS(1000, MATCH($B12, Attendance_data!$E$3:$BI$3, 0) + 4)), "A" ) ),"")} -> 0.6 | W12: {=IFERROR( COUNTIFS(Attendance_data!$B$4:$B$1000,W$4, INDIRECT("Attendance_data!" & ADDRESS(4, MATCH($B12, Attendance_data!$E$3:$BI$3, 0) + 4) & ":" & ADDRESS(1000, MATCH($B12, Attendance_data!$E$3:$BI$3, 0) + 4)), "P" ) / ( COUNTIFS( Attendance_data!$B$4:$B$1000,W$4, INDIRECT("Attendance_data!" & ADDRESS(4, MATCH($B12, Attendance_data!$E$3:$BI$3, 0) + 4) & ":" & ADDRESS(1000, MATCH($B12, Attendance_data!$E$3:$BI$3, 0) + 4)), "P" ) + COUNTIFS( Attendance_data!$B$4:$B$1000,W$4, INDIRECT("Attendance_data!" & ADDRESS(4, MATCH($B12, Attendance_data!$E$3:$BI$3, 0) + 4) & ":" & ADDRESS(1000, MATCH($B12, Attendance_data!$E$3:$BI$3, 0) + 4)), "A" ) ),"")} -> 1 | ... AA12: {=IFERROR( COUNTIFS(Attendance_data!$B$4:$B$1000,AA$4, INDIRECT("Attendance_data!" & ADDRESS(4, MATCH($B12, Attendance_data!$E$3:$BI$3, 0) + 4) & ":" & ADDRESS(1000, MATCH($B12, Attendance_data!$E$3:$BI$3, 0) + 4)), "P" ) / ( COUNTIFS( Attendance_data!$B$4:$B$1000,AA$4, INDIRECT("Attendance_data!" & ADDRESS(4, MATCH($B12, Attendance_data!$E$3:$BI$3, 0) + 4) & ":" & ADDRESS(1000, MATCH($B12, Attendance_data!$E$3:$BI$3, 0) + 4)), "P" ) + COUNTIFS( Attendance_data!$B$4:$B$1000,AA$4, INDIRECT("Attendance_data!" & ADDRESS(4, MATCH($B12, Attendance_data!$E$3:$BI$3, 0) + 4) & ":" & ADDRESS(1000, MATCH($B12, Attendance_data!$E$3:$BI$3, 0) + 4)), "A" ) ),"")} | AB12: =AVERAGEIF(P12:Z12,">0") -> 0.75067637
A13: =ROW()-4 -> 9 | B13: NMUD33 | C13: Aditya Gyaniram Mohare | D13: 9th | E13: Boy | F13: 8291213490 | G13: Playing Kabaddi | H13: 2021 | I13: Active | J13: 30 | K13: 26 | L13: 27 | M13: 29 | N13: 30 | O13: 26 | P13: {=IFERROR( COUNTIFS(Attendance_data!$B$4:$B$1000,P$4, INDIRECT("Attendance_data!" & ADDRESS(4, MATCH($B13, Attendance_data!$E$3:$BI$3, 0) + 4) & ":" & ADDRESS(1000, MATCH($B13, Attendance_data!$E$3:$BI$3, 0) + 4)), "P" ) / ( COUNTIFS( Attendance_data!$B$4:$B$1000,P$4, INDIRECT("Attendance_data!" & ADDRESS(4, MATCH($B13, Attendance_data!$E$3:$BI$3, 0) + 4) & ":" & ADDRESS(1000, MATCH($B13, Attendance_data!$E$3:$BI$3, 0) + 4)), "P" ) + COUNTIFS( Attendance_data!$B$4:$B$1000,P$4, INDIRECT("Attendance_data!" & ADDRESS(4, MATCH($B13, Attendance_data!$E$3:$BI$3, 0) + 4) & ":" & ADDRESS(1000, MATCH($B13, Attendance_data!$E$3:$BI$3, 0) + 4)), "A" ) ),"")} -> 1 | Q13: {=IFERROR( COUNTIFS(Attendance_data!$B$4:$B$1000,Q$4, INDIRECT("Attendance_data!" & ADDRESS(4, MATCH($B13, Attendance_data!$E$3:$BI$3, 0) + 4) & ":" & ADDRESS(1000, MATCH($B13, Attendance_data!$E$3:$BI$3, 0) + 4)), "P" ) / ( COUNTIFS( Attendance_data!$B$4:$B$1000,Q$4, INDIRECT("Attendance_data!" & ADDRESS(4, MATCH($B13, Attendance_data!$E$3:$BI$3, 0) + 4) & ":" & ADDRESS(1000, MATCH($B13, Attendance_data!$E$3:$BI$3, 0) + 4)), "P" ) + COUNTIFS( Attendance_data!$B$4:$B$1000,Q$4, INDIRECT("Attendance_data!" & ADDRESS(4, MATCH($B13, Attendance_data!$E$3:$BI$3, 0) + 4) & ":" & ADDRESS(1000, MATCH($B13, Attendance_data!$E$3:$BI$3, 0) + 4)), "A" ) ),"")} -> 0.92307692 | R13: {=IFERROR( COUNTIFS(Attendance_data!$B$4:$B$1000,R$4, INDIRECT("Attendance_data!" & ADDRESS(4, MATCH($B13, Attendance_data!$E$3:$BI$3, 0) + 4) & ":" & ADDRESS(1000, MATCH($B13, Attendance_data!$E$3:$BI$3, 0) + 4)), "P" ) / ( COUNTIFS( Attendance_data!$B$4:$B$1000,R$4, INDIRECT("Attendance_data!" & ADDRESS(4, MATCH($B13, Attendance_data!$E$3:$BI$3, 0) + 4) & ":" & ADDRESS(1000, MATCH($B13, Attendance_data!$E$3:$BI$3, 0) + 4)), "P" ) + COUNTIFS( Attendance_data!$B$4:$B$1000,R$4, INDIRECT("Attendance_data!" & ADDRESS(4, MATCH($B13, Attendance_data!$E$3:$BI$3, 0) + 4) & ":" & ADDRESS(1000, MATCH($B13, Attendance_data!$E$3:$BI$3, 0) + 4)), "A" ) ),"")} -> 0.36842105 | S13: {=IFERROR( COUNTIFS(Attendance_data!$B$4:$B$1000,S$4, INDIRECT("Attendance_data!" & ADDRESS(4, MATCH($B13, Attendance_data!$E$3:$BI$3, 0) + 4) & ":" & ADDRESS(1000, MATCH($B13, Attendance_data!$E$3:$BI$3, 0) + 4)), "P" ) / ( COUNTIFS( Attendance_data!$B$4:$B$1000,S$4, INDIRECT("Attendance_data!" & ADDRESS(4, MATCH($B13, Attendance_data!$E$3:$BI$3, 0) + 4) & ":" & ADDRESS(1000, MATCH($B13, Attendance_data!$E$3:$BI$3, 0) + 4)), "P" ) + COUNTIFS( Attendance_data!$B$4:$B$1000,S$4, INDIRECT("Attendance_data!" & ADDRESS(4, MATCH($B13, Attendance_data!$E$3:$BI$3, 0) + 4) & ":" & ADDRESS(1000, MATCH($B13, Attendance_data!$E$3:$BI$3, 0) + 4)), "A" ) ),"")} -> 0.68181818 | T13: {=IFERROR( COUNTIFS(Attendance_data!$B$4:$B$1000,T$4, INDIRECT("Attendance_data!" & ADDRESS(4, MATCH($B13, Attendance_data!$E$3:$BI$3, 0) + 4) & ":" & ADDRESS(1000, MATCH($B13, Attendance_data!$E$3:$BI$3, 0) + 4)), "P" ) / ( COUNTIFS( Attendance_data!$B$4:$B$1000,T$4, INDIRECT("Attendance_data!" & ADDRESS(4, MATCH($B13, Attendance_data!$E$3:$BI$3, 0) + 4) & ":" & ADDRESS(1000, MATCH($B13, Attendance_data!$E$3:$BI$3, 0) + 4)), "P" ) + COUNTIFS( Attendance_data!$B$4:$B$1000,T$4, INDIRECT("Attendance_data!" & ADDRESS(4, MATCH($B13, Attendance_data!$E$3:$BI$3, 0) + 4) & ":" & ADDRESS(1000, MATCH($B13, Attendance_data!$E$3:$BI$3, 0) + 4)), "A" ) ),"")} -> 0.9 | U13: {=IFERROR( COUNTIFS(Attendance_data!$B$4:$B$1000,U$4, INDIRECT("Attendance_data!" & ADDRESS(4, MATCH($B13, Attendance_data!$E$3:$BI$3, 0) + 4) & ":" & ADDRESS(1000, MATCH($B13, Attendance_data!$E$3:$BI$3, 0) + 4)), "P" ) / ( COUNTIFS( Attendance_data!$B$4:$B$1000,U$4, INDIRECT("Attendance_data!" & ADDRESS(4, MATCH($B13, Attendance_data!$E$3:$BI$3, 0) + 4) & ":" & ADDRESS(1000, MATCH($B13, Attendance_data!$E$3:$BI$3, 0) + 4)), "P" ) + COUNTIFS( Attendance_data!$B$4:$B$1000,U$4, INDIRECT("Attendance_data!" & ADDRESS(4, MATCH($B13, Attendance_data!$E$3:$BI$3, 0) + 4) & ":" & ADDRESS(1000, MATCH($B13, Attendance_data!$E$3:$BI$3, 0) + 4)), "A" ) ),"")} -> 0.8 | V13: {=IFERROR( COUNTIFS(Attendance_data!$B$4:$B$1000,V$4, INDIRECT("Attendance_data!" & ADDRESS(4, MATCH($B13, Attendance_data!$E$3:$BI$3, 0) + 4) & ":" & ADDRESS(1000, MATCH($B13, Attendance_data!$E$3:$BI$3, 0) + 4)), "P" ) / ( COUNTIFS( Attendance_data!$B$4:$B$1000,V$4, INDIRECT("Attendance_data!" & ADDRESS(4, MATCH($B13, Attendance_data!$E$3:$BI$3, 0) + 4) & ":" & ADDRESS(1000, MATCH($B13, Attendance_data!$E$3:$BI$3, 0) + 4)), "P" ) + COUNTIFS( Attendance_data!$B$4:$B$1000,V$4, INDIRECT("Attendance_data!" & ADDRESS(4, MATCH($B13, Attendance_data!$E$3:$BI$3, 0) + 4) & ":" & ADDRESS(1000, MATCH($B13, Attendance_data!$E$3:$BI$3, 0) + 4)), "A" ) ),"")} -> 0.88 | W13: {=IFERROR( COUNTIFS(Attendance_data!$B$4:$B$1000,W$4, INDIRECT("Attendance_data!" & ADDRESS(4, MATCH($B13, Attendance_data!$E$3:$BI$3, 0) + 4) & ":" & ADDRESS(1000, MATCH($B13, Attendance_data!$E$3:$BI$3, 0) + 4)), "P" ) / ( COUNTIFS( Attendance_data!$B$4:$B$1000,W$4, INDIRECT("Attendance_data!" & ADDRESS(4, MATCH($B13, Attendance_data!$E$3:$BI$3, 0) + 4) & ":" & ADDRESS(1000, MATCH($B13, Attendance_data!$E$3:$BI$3, 0) + 4)), "P" ) + COUNTIFS( Attendance_data!$B$4:$B$1000,W$4, INDIRECT("Attendance_data!" & ADDRESS(4, MATCH($B13, Attendance_data!$E$3:$BI$3, 0) + 4) & ":" & ADDRESS(1000, MATCH($B13, Attendance_data!$E$3:$BI$3, 0) + 4)), "A" ) ),"")} -> 0.72 | ... AA13: {=IFERROR( COUNTIFS(Attendance_data!$B$4:$B$1000,AA$4, INDIRECT("Attendance_data!" & ADDRESS(4, MATCH($B13, Attendance_data!$E$3:$BI$3, 0) + 4) & ":" & ADDRESS(1000, MATCH($B13, Attendance_data!$E$3:$BI$3, 0) + 4)), "P" ) / ( COUNTIFS( Attendance_data!$B$4:$B$1000,AA$4, INDIRECT("Attendance_data!" & ADDRESS(4, MATCH($B13, Attendance_data!$E$3:$BI$3, 0) + 4) & ":" & ADDRESS(1000, MATCH($B13, Attendance_data!$E$3:$BI$3, 0) + 4)), "P" ) + COUNTIFS( Attendance_data!$B$4:$B$1000,AA$4, INDIRECT("Attendance_data!" & ADDRESS(4, MATCH($B13, Attendance_data!$E$3:$BI$3, 0) + 4) & ":" & ADDRESS(1000, MATCH($B13, Attendance_data!$E$3:$BI$3, 0) + 4)), "A" ) ),"")} | AB13: =AVERAGEIF(P13:Z13,">0") -> 0.76258141
